Workbook
Name 切片器_标签筛选: #N/A
Name 切片器_标签筛选1: #N/A
Name 切片器_列1: #N/A

Sheet 3
B3: 属性 | C3: 标签
D4: ='1'!B1 -> 新建 文本文档 | E4: ='1'!C1 -> 0 | F4: ='1'!D1 -> 0 | G4: ='1'!E1 -> 0 | H4: ='1'!F1 -> 0 | I4: ='1'!G1 -> 0 | J4: ='1'!H1 -> 0 | K4: ='1'!I1 -> 0 | L4: ='1'!J1 -> 0
A5: 标签筛选 | B5: 人群总量级 | D5: ='1'!B2 -> 42410 | E5: ='1'!C2 -> 0 | F5: ='1'!D2 -> 0 | G5: ='1'!E2 -> 0 | H5: ='1'!F2 -> 0 | I5: ='1'!G2 -> 0 | J5: ='1'!H2 -> 0 | K5: ='1'!I2 -> 0 | L5: ='1'!J2 -> 0
A6: 性别 | B6: 性别 | C6: 男 | D6: ='1'!B3 -> 0.0426 | E6: ='1'!C3 -> 0 | F6: ='1'!D3 -> 0 | G6: ='1'!E3 -> 0 | H6: ='1'!F3 -> 0 | I6: ='1'!G3 -> 0 | J6: ='1'!H3 -> 0 | K6: ='1'!I3 -> 0 | L6: ='1'!J3 -> 0
A7: 性别 | C7: 女 | D7: ='1'!B4 -> 0.9566 | E7: ='1'!C4 -> 0 | F7: ='1'!D4 -> 0 | G7: ='1'!E4 -> 0 | H7: ='1'!F4 -> 0 | I7: ='1'!G4 -> 0 | J7: ='1'!H4 -> 0 | K7: ='1'!I4 -> 0 | L7: ='1'!J4 -> 0
A8: 性别 | C8: 性别未知 | D8: ='1'!B5 -> 0.0008 | E8: ='1'!C5 -> 0 | F8: ='1'!D5 -> 0 | G8: ='1'!E5 -> 0 | H8: ='1'!F5 -> 0 | I8: ='1'!G5 -> 0 | J8: ='1'!H5 -> 0 | K8: ='1'!I5 -> 0 | L8: ='1'!J5 -> 0
A9: 购买者年龄分布 | B9: 购买者年龄分布 | C9: 平均年龄预估 | D9: =21*D10+27*D11+32*D12+37*D13+42*D14+45*D15 -> 28.695 | E9: =21*E10+27*E11+32*E12+37*E13+42*E14+45*E15 -> 0 | F9: =21*F10+27*F11+32*F12+37*F13+42*F14+45*F15 -> 0 | G9: =21*G10+27*G11+32*G12+37*G13+42*G14+45*G15 -> 0 | H9: =21*H10+27*H11+32*H12+37*H13+42*H14+45*H15 -> 0 | I9: =21*I10+27*I11+32*I12+37*I13+42*I14+45*I15 -> 0 | J9: =21*J10+27*J11+32*J12+37*J13+42*J14+45*J15 -> 0 | K9: =21*K10+27*K11+32*K12+37*K13+42*K14+45*K15 -> 0 | L9: =21*L10+27*L11+32*L12+37*L13+42*L14+45*L15 -> 0
A10: 购买者年龄分布 | C10: 18-24 | D10: ='1'!B6 -> 0.2382 | E10: ='1'!C6 -> 0 | F10: ='1'!D6 -> 0 | G10: ='1'!E6 -> 0 | H10: ='1'!F6 -> 0 | I10: ='1'!G6 -> 0 | J10: ='1'!H6 -> 0 | K10: ='1'!I6 -> 0 | L10: ='1'!J6 -> 0
A11: 购买者年龄分布 | C11: 25-29 | D11: ='1'!B7 -> 0.3807 | E11: ='1'!C7 -> 0 | F11: ='1'!D7 -> 0 | G11: ='1'!E7 -> 0 | H11: ='1'!F7 -> 0 | I11: ='1'!G7 -> 0 | J11: ='1'!H7 -> 0 | K11: ='1'!I7 -> 0 | L11: ='1'!J7 -> 0
A12: 购买者年龄分布 | C12: 30-34 | D12: ='1'!B8 -> 0.202 | E12: ='1'!C8 -> 0 | F12: ='1'!D8 -> 0 | G12: ='1'!E8 -> 0 | H12: ='1'!F8 -> 0 | I12: ='1'!G8 -> 0 | J12: ='1'!H8 -> 0 | K12: ='1'!I8 -> 0 | L12: ='1'!J8 -> 0
A13: 购买者年龄分布 | C13: 35-39 | D13: ='1'!B9 -> 0.1066 | E13: ='1'!C9 -> 0 | F13: ='1'!D9 -> 0 | G13: ='1'!E9 -> 0 | H13: ='1'!F9 -> 0 | I13: ='1'!G9 -> 0 | J13: ='1'!H9 -> 0 | K13: ='1'!I9 -> 0 | L13: ='1'!J9 -> 0
A14: 购买者年龄分布 | C14: 40-44 | D14: ='1'!B10 -> 0.0346 | E14: ='1'!C10 -> 0 | F14: ='1'!D10 -> 0 | G14: ='1'!E10 -> 0 | H14: ='1'!F10 -> 0 | I14: ='1'!G10 -> 0 | J14: ='1'!H10 -> 0 | K14: ='1'!I10 -> 0 | L14: ='1'!J10 -> 0
A15: 购买者年龄分布 | C15: 45+ | D15: ='1'!B11+'1'!B12+'1'!B13+'1'!B14 -> 0.0345 | E15: ='1'!C11+'1'!C12+'1'!C13+'1'!C14 -> 0 | F15: ='1'!D11+'1'!D12+'1'!D13+'1'!D14 -> 0 | G15: ='1'!E11+'1'!E12+'1'!E13+'1'!E14 -> 0 | H15: ='1'!F11+'1'!F12+'1'!F13+'1'!F14 -> 0 | I15: ='1'!G11+'1'!G12+'1'!G13+'1'!G14 -> 0 | J15: ='1'!H11+'1'!H12+'1'!H13+'1'!H14 -> 0 | K15: ='1'!I11+'1'!I12+'1'!I13+'1'!I14 -> 0 | L15: ='1'!J11+'1'!J12+'1'!J13+'1'!J14 -> 0
A16: 购买者年龄分布 | C16: 年龄未知 | D16: ='1'!B15 -> 0.0033 | E16: ='1'!C15 -> 0 | F16: ='1'!D15 -> 0 | G16: ='1'!E15 -> 0 | H16: ='1'!F15 -> 0 | I16: ='1'!G15 -> 0 | J16: ='1'!H15 -> 0 | K16: ='1'!I15 -> 0 | L16: ='1'!J15 -> 0
A17: 购买者所处城市等级 | B17: 购买者所处城市等级 | C17: City Tier 1 | D17: ='1'!B16 -> 0.1344 | E17: ='1'!C16 -> 0 | F17: ='1'!D16 -> 0 | G17: ='1'!E16 -> 0 | H17: ='1'!F16 -> 0 | I17: ='1'!G16 -> 0 | J17: ='1'!H16 -> 0 | K17: ='1'!I16 -> 0 | L17: ='1'!J16 -> 0
A18: 购买者所处城市等级 | C18: City Tier 2 | D18: ='1'!B17 -> 0.3293 | E18: ='1'!C17 -> 0 | F18: ='1'!D17 -> 0 | G18: ='1'!E17 -> 0 | H18: ='1'!F17 -> 0 | I18: ='1'!G17 -> 0 | J18: ='1'!H17 -> 0 | K18: ='1'!I17 -> 0 | L18: ='1'!J17 -> 0
A19: 购买者所处城市等级 | C19: City Tier 3 | D19: ='1'!B18 -> 0.2034 | E19: ='1'!C18 -> 0 | F19: ='1'!D18 -> 0 | G19: ='1'!E18 -> 0 | H19: ='1'!F18 -> 0 | I19: ='1'!G18 -> 0 | J19: ='1'!H18 -> 0 | K19: ='1'!I18 -> 0 | L19: ='1'!J18 -> 0
A20: 购买者所处城市等级 | C20: City Tier 4 | D20: ='1'!B19 -> 0.089 | E20: ='1'!C19 -> 0 | F20: ='1'!D19 -> 0 | G20: ='1'!E19 -> 0 | H20: ='1'!F19 -> 0 | I20: ='1'!G19 -> 0 | J20: ='1'!H19 -> 0 | K20: ='1'!I19 -> 0 | L20: ='1'!J19 -> 0
A21: 购买者所处城市等级 | C21: City Tier 5 | D21: ='1'!B20 -> 0.1452 | E21: ='1'!C20 -> 0 | F21: ='1'!D20 -> 0 | G21: ='1'!E20 -> 0 | H21: ='1'!F20 -> 0 | I21: ='1'!G20 -> 0 | J21: ='1'!H20 -> 0 | K21: ='1'!I20 -> 0 | L21: ='1'!J20 -> 0
A22: 购买者所处城市等级 | C22: City Tier 6 | D22: ='1'!B21 -> 0.0951 | E22: ='1'!C21 -> 0 | F22: ='1'!D21 -> 0 | G22: ='1'!E21 -> 0 | H22: ='1'!F21 -> 0 | I22: ='1'!G21 -> 0 | J22: ='1'!H21 -> 0 | K22: ='1'!I21 -> 0 | L22: ='1'!J21 -> 0
A23: 购买者所处城市等级 | C23: 城市等级未知 | D23: ='1'!B22 -> 0.0036 | E23: ='1'!C22 -> 0 | F23: ='1'!D22 -> 0 | G23: ='1'!E22 -> 0 | H23: ='1'!F22 -> 0 | I23: ='1'!G22 -> 0 | J23: ='1'!H22 -> 0 | K23: ='1'!I22 -> 0 | L23: ='1'!J22 -> 0
A24: 预测购买力 | B24: 预测购买力 | C24: 1 | D24: ='1'!B23 -> 0.0071 | E24: ='1'!C23 -> 0 | F24: ='1'!D23 -> 0 | G24: ='1'!E23 -> 0 | H24: ='1'!F23 -> 0 | I24: ='1'!G23 -> 0 | J24: ='1'!H23 -> 0 | K24: ='1'!I23 -> 0 | L24: ='1'!J23 -> 0
A25: 预测购买力 | C25: 2 | D25: ='1'!B24 -> 0.0836 | E25: ='1'!C24 -> 0 | F25: ='1'!D24 -> 0 | G25: ='1'!E24 -> 0 | H25: ='1'!F24 -> 0 | I25: ='1'!G24 -> 0 | J25: ='1'!H24 -> 0 | K25: ='1'!I24 -> 0 | L25: ='1'!J24 -> 0
A26: 预测购买力 | C26: 3 | D26: ='1'!B25 -> 0.2289 | E26: ='1'!C25 -> 0 | F26: ='1'!D25 -> 0 | G26: ='1'!E25 -> 0 | H26: ='1'!F25 -> 0 | I26: ='1'!G25 -> 0 | J26: ='1'!H25 -> 0 | K26: ='1'!I25 -> 0 | L26: ='1'!J25 -> 0
A27: 预测购买力 | C27: 4 | D27: ='1'!B26 -> 0.3504 | E27: ='1'!C26 -> 0 | F27: ='1'!D26 -> 0 | G27: ='1'!E26 -> 0 | H27: ='1'!F26 -> 0 | I27: ='1'!G26 -> 0 | J27: ='1'!H26 -> 0 | K27: ='1'!I26 -> 0 | L27: ='1'!J26 -> 0
A28: 预测购买力 | C28: 5 | D28: ='1'!B27 -> 0.3296 | E28: ='1'!C27 -> 0 | F28: ='1'!D27 -> 0 | G28: ='1'!E27 -> 0 | H28: ='1'!F27 -> 0 | I28: ='1'!G27 -> 0 | J28: ='1'!H27 -> 0 | K28: ='1'!I27 -> 0 | L28: ='1'!J27 -> 0
A29: 预测购买力 | C29: 购买力未知 | D29: ='1'!B28 -> 0.0004 | E29: ='1'!C28 -> 0 | F29: ='1'!D28 -> 0 | G29: ='1'!E28 -> 0 | H29: ='1'!F28 -> 0 | I29: ='1'!G28 -> 0 | J29: ='1'!H28 -> 0 | K29: ='1'!I28 -> 0 | L29: ='1'!J28 -> 0
A30: 护肤年消费金额 | B30: 护肤年消费金额 | C30: 0-1000元 | D30: ='1'!B30+'1'!B31+'1'!B32+'1'!B33+'1'!B34+'1'!B35+'1'!B29 -> 0.271 | E30: ='1'!C30+'1'!C31+'1'!C32+'1'!C33+'1'!C34+'1'!C35+'1'!C29 -> 0 | F30: ='1'!D30+'1'!D31+'1'!D32+'1'!D33+'1'!D34+'1'!D35+'1'!D29 -> 0 | G30: ='1'!E30+'1'!E31+'1'!E32+'1'!E33+'1'!E34+'1'!E35+'1'!E29 -> 0 | H30: ='1'!F30+'1'!F31+'1'!F32+'1'!F33+'1'!F34+'1'!F35+'1'!F29 -> 0 | I30: ='1'!G30+'1'!G31+'1'!G32+'1'!G33+'1'!G34+'1'!G35+'1'!G29 -> 0 | J30: ='1'!H30+'1'!H31+'1'!H32+'1'!H33+'1'!H34+'1'!H35+'1'!H29 -> 0 | K30: ='1'!I30+'1'!I31+'1'!I32+'1'!I33+'1'!I34+'1'!I35+'1'!I29 -> 0 | L30: ='1'!J30+'1'!J31+'1'!J32+'1'!J33+'1'!J34+'1'!J35+'1'!J29 -> 0
A31: 护肤年消费金额 | C31: 1000-1499元 | D31: ='1'!B36 -> 0.1017 | E31: ='1'!C36 -> 0 | F31: ='1'!D36 -> 0 | G31: ='1'!E36 -> 0 | H31: ='1'!F36 -> 0 | I31: ='1'!G36 -> 0 | J31: ='1'!H36 -> 0 | K31: ='1'!I36 -> 0 | L31: ='1'!J36 -> 0
A32: 护肤年消费金额 | C32: 1500-1999元 | D32: ='1'!B37 -> 0.0878 | E32: ='1'!C37 -> 0 | F32: ='1'!D37 -> 0 | G32: ='1'!E37 -> 0 | H32: ='1'!F37 -> 0 | I32: ='1'!G37 -> 0 | J32: ='1'!H37 -> 0 | K32: ='1'!I37 -> 0 | L32: ='1'!J37 -> 0
A33: 护肤年消费金额 | C33: 2000-4999元 | D33: ='1'!B38 -> 0.3041 | E33: ='1'!C38 -> 0 | F33: ='1'!D38 -> 0 | G33: ='1'!E38 -> 0 | H33: ='1'!F38 -> 0 | I33: ='1'!G38 -> 0 | J33: ='1'!H38 -> 0 | K33: ='1'!I38 -> 0 | L33: ='1'!J38 -> 0
A34: 护肤年消费金额 | C34: 5000元及以上 | D34: ='1'!B39 -> 0.2354 | E34: ='1'!C39 -> 0 | F34: ='1'!D39 -> 0 | G34: ='1'!E39 -> 0 | H34: ='1'!F39 -> 0 | I34: ='1'!G39 -> 0 | J34: ='1'!H39 -> 0 | K34: ='1'!I39 -> 0 | L34: ='1'!J39 -> 0
A35: 护肤年消费频次 | B35: 护肤年消费频次 | C35: 0-5次 | D35: ='1'!B40+'1'!B41+'1'!B42+'1'!B43+'1'!B44 -> 0.1942 | E35: ='1'!C40+'1'!C41+'1'!C42+'1'!C43+'1'!C44 -> 0 | F35: ='1'!D40+'1'!D41+'1'!D42+'1'!D43+'1'!D44 -> 0 | G35: ='1'!E40+'1'!E41+'1'!E42+'1'!E43+'1'!E44 -> 0 | H35: ='1'!F40+'1'!F41+'1'!F42+'1'!F43+'1'!F44 -> 0 | I35: ='1'!G40+'1'!G41+'1'!G42+'1'!G43+'1'!G44 -> 0 | J35: ='1'!H40+'1'!H41+'1'!H42+'1'!H43+'1'!H44 -> 0 | K35: ='1'!I40+'1'!I41+'1'!I42+'1'!I43+'1'!I44 -> 0 | L35: ='1'!J40+'1'!J41+'1'!J42+'1'!J43+'1'!J44 -> 0
A36: 护肤年消费频次 | C36: 6-10次 | D36: ='1'!B45+'1'!B46 -> 0.2087 | E36: ='1'!C45+'1'!C46 -> 0 | F36: ='1'!D45+'1'!D46 -> 0 | G36: ='1'!E45+'1'!E46 -> 0 | H36: ='1'!F45+'1'!F46 -> 0 | I36: ='1'!G45+'1'!G46 -> 0 | J36: ='1'!H45+'1'!H46 -> 0 | K36: ='1'!I45+'1'!I46 -> 0 | L36: ='1'!J45+'1'!J46 -> 0
A37: 护肤年消费频次 | C37: 11-12次 | D37: ='1'!B47 -> 0.0759 | E37: ='1'!C47 -> 0 | F37: ='1'!D47 -> 0 | G37: ='1'!E47 -> 0 | H37: ='1'!F47 -> 0 | I37: ='1'!G47 -> 0 | J37: ='1'!H47 -> 0 | K37: ='1'!I47 -> 0 | L37: ='1'!J47 -> 0
A38: 护肤年消费频次 | C38: 13次及以上 | D38: ='1'!B48 -> 0.5212 | E38: ='1'!C48 -> 0 | F38: ='1'!D48 -> 0 | G38: ='1'!E48 -> 0 | H38: ='1'!F48 -> 0 | I38: ='1'!G48 -> 0 | J38: ='1'!H48 -> 0 | K38: ='1'!I48 -> 0 | L38: ='1'!J48 -> 0
A39: 彩妆年消费金额 | B39: 彩妆年消费金额 | C39: 0元 | D39: ='1'!B69 -> 0.0014 | E39: ='1'!C69 -> 0 | F39: ='1'!D69 -> 0 | G39: ='1'!E69 -> 0 | H39: ='1'!F69 -> 0 | I39: ='1'!G69 -> 0 | J39: ='1'!H69 -> 0 | K39: ='1'!I69 -> 0 | L39: ='1'!J69 -> 0
A40: 彩妆年消费金额 | C40: 1-200元 | D40: ='1'!B70+'1'!B71 -> 0.0016 | E40: ='1'!C70+'1'!C71 -> 0 | F40: ='1'!D70+'1'!D71 -> 0 | G40: ='1'!E70+'1'!E71 -> 0 | H40: ='1'!F70+'1'!F71 -> 0 | I40: ='1'!G70+'1'!G71 -> 0 | J40: ='1'!H70+'1'!H71 -> 0 | K40: ='1'!I70+'1'!I71 -> 0 | L40: ='1'!J70+'1'!J71 -> 0
A41: 彩妆年消费金额 | C41: 200-500元 | D41: ='1'!B72+'1'!B73 -> 0.0292 | E41: ='1'!C72+'1'!C73 -> 0 | F41: ='1'!D72+'1'!D73 -> 0 | G41: ='1'!E72+'1'!E73 -> 0 | H41: ='1'!F72+'1'!F73 -> 0 | I41: ='1'!G72+'1'!G73 -> 0 | J41: ='1'!H72+'1'!H73 -> 0 | K41: ='1'!I72+'1'!I73 -> 0 | L41: ='1'!J72+'1'!J73 -> 0
A42: 彩妆年消费金额 | C42: 500-1000元 | D42: ='1'!B74+'1'!B75 -> 0.1774 | E42: ='1'!C74+'1'!C75 -> 0 | F42: ='1'!D74+'1'!D75 -> 0 | G42: ='1'!E74+'1'!E75 -> 0 | H42: ='1'!F74+'1'!F75 -> 0 | I42: ='1'!G74+'1'!G75 -> 0 | J42: ='1'!H74+'1'!H75 -> 0 | K42: ='1'!I74+'1'!I75 -> 0 | L42: ='1'!J74+'1'!J75 -> 0
...

Sheet 1
A1: A | B1: 新建 文本文档
A2: 人群量级 | B2: 42410
A3: 性别男 | B3: 0.0426
A4: 性别女 | B4: 0.9566
A5: 性别未知 | B5: 0.0008
A6: 年龄[18,24] | B6: 0.2382
A7: 年龄[25,29] | B7: 0.3807
A8: 年龄[30,34] | B8: 0.202
A9: 年龄[35,39] | B9: 0.1066
A10: 年龄[40,44] | B10: 0.0346
A11: 年龄[45,49] | B11: 0.0145
A12: 年龄[50,54] | B12: 0.0096
A13: 年龄[55,59] | B13: 0.0043
... A57: 策略人群都市银发族 | B57: 0.011
A58: 策略人群未知
A59: 十大策略人群精致女性
A60: 十大策略人群小镇新贵
A61: 十大策略人群都市型男
A62: 十大策略人群悦己青年
A63: 十大策略人群小镇中坚
A64: 十大策略人群实惠大众
A65: 十大策略人群资深中产
A66: 十大策略人群品质银发
A67: 十大策略人群简朴银发
A68: 十大策略人群平价青年
A69: 彩妆年消费金额0元 | B69: 0.0014
A70: 彩妆年消费金额1-99元 | B70: 0.0009
A71: 彩妆年消费金额100-199元 | B71: 0.0007
A72: 彩妆年消费金额200-299元 | B72: 0.0004
A73: 彩妆年消费金额300-499元 | B73: 0.0288
A74: 彩妆年消费金额500-799元 | B74: 0.1047
A75: 彩妆年消费金额800-999元 | B75: 0.0727
A76: 彩妆年消费金额1000-1499元 | B76: 0.1805
A77: 彩妆年消费金额1500-1999元 | B77: 0.1435
A78: 彩妆年消费金额2000-4999元 | B78: 0.3534
A79: 彩妆年消费金额5000元及以上 | B79: 0.113
A80: 彩妆年消费频次0次 | B80: 0.0014
... A88: 彩妆年消费频次13次及以上 | B88: 0.5631
A89: 月均消费金额0-499元
A90: 月均消费金额500-999元
...
